Workbook

Sheet 1_Phan_tich_yeu_cau
A1: PHÂN TÍCH YÊU CẦU - WEB QUYÊN GÓP TỪ THIỆN
A2: Ngữ cảnh dự án | B2: Website cho phép người dùng đăng ký/đăng nhập, xem chiến dịch, quyên góp, xem lịch sử; admin quản lý chiến dịch, người dùng và xem thống kê.
A3: Công nghệ chính | B3: Frontend React.js+ Vite; Backend Node.js/Express.js; MySQL; JWT; bcrypt; Multer; UI Tailwind CSS/Ant Design;Smart Contract Solidity + Hardhat + OpenZeppelin; IPFS metadata; Google OAuth + Wallet login.
A5: 1. Danh sách chức năng
A6: Mã | B6: Nhóm | C6: Chức năng | D6: Mô tả | E6: Actor | F6: Ưu tiên
A7: F01 | B7: Người dùng | C7: Đăng ký tài khoản | D7: Tạo tài khoản mới bằng họ tên, email, mật khẩu; phân quyền mặc định là user. | E7: Khách | F7: Cao
A8: F02 | B8: Người dùng | C8: Đăng nhập/đăng xuất | D8: Xác thực bằng email + mật khẩu, cấp JWT khi đăng nhập thành công, cho phép đăng xuất. | E8: Khách/Người dùng | F8: Cao
A9: F03 | B9: Người dùng | C9: Xem danh sách chiến dịch | D9: Hiển thị các chiến dịch từ thiện, trạng thái, số tiền mục tiêu/đã quyên góp, ngày bắt đầu/kết thúc. | E9: Khách/Người dùng | F9: Cao
A10: F04 | B10: Người dùng | C10: Xem chi tiết chiến dịch | D10: Xem mô tả, hình ảnh, tiến độ, thời gian chiến dịch và nút quyên góp. | E10: Khách/Người dùng | F10: Cao
A11: F05 | B11: Người dùng | C11: Quyên góp tiền | D11: Tạo khoản quyên góp cho chiến dịch đang hoạt động; ghi nhận số tiền, thời gian, giao dịch thanh toán. | E11: Người dùng | F11: Rất cao
A12: F06 | B12: Người dùng | C12: Xem lịch sử quyên góp | D12: Người dùng xem các lần quyên góp của chính mình theo chiến dịch, thời gian, số tiền, trạng thái. | E12: Người dùng | F12: Trung bình
A13: F07 | B13: Quản trị | C13: Quản lý chiến dịch (CRUD) | D13: Admin tạo, sửa, ẩn/hiện và cập nhật trạng thái chiến dịch. | E13: Admin | F13: Rất cao
A14: F08 | B14: Quản trị | C14: Quản lý người dùng | D14: Admin xem danh sách người dùng, vai trò và trạng thái tài khoản. | E14: Admin | F14: Cao
A15: F09 | B15: Quản trị | C15: Xem thống kê/báo cáo | D15: Admin xem tổng số tiền quyên góp, số chiến dịch, số lượt quyên góp và số người dùng. | E15: Admin | F15: Cao
A16: F10 | B16: Hệ thống | C16: Quản lý giao dịch | D16: Liên kết mỗi khoản quyên góp với bản ghi giao dịch (phương thức thanh toán, trạng thái). | E16: Hệ thống/Admin | F16: Cao
A19: Hải
A20: F01 | B20: Smart Contract | C20: Tạo Vault (Factory) | D20: Operator deploy HopeFundVault mới cho từng project; mỗi projectId chỉ 1 vault duy nhất. | E20: Admin/Operator | F20: Rất cao
A21: F02 | B21: Smart Contract | C21: Chuyển quyền operator | D21: Operator hiện tại chuyển quyền tạo vault cho địa chỉ mới. | E21: Operator | F21: Trung bình
A22: F03 | B22: Smart Contract | C22: Donate token vào vault | D22: Người dùng chuyển USDT vào vault của project; tối thiểu 0.1 token (MIN_DONATION = 1e17). | E22: User | F22: Rất cao
A23: F04 | B23: Smart Contract | C23: Founder claim (EIP-712) | D23: Founder rút tiền từ vault bằng chữ ký EIP-712 của adminSigner; chống replay attack bằng nonce + deadline. | E23: Founder | F23: Rất cao
A24: F05 | B24: Smart Contract | C24: Pause/Unpause vault | D24: AdminSigner tạm dừng hoặc mở lại hoạt động donate/claim của vault. | E24: AdminSigner | F24: Cao
A25: F06 | B25: Smart Contract | C25: Thay đổi admin signer | D25: AdminSigner hiện tại đổi sang địa chỉ admin mới. | E25: AdminSigner | F25: Trung bình
A26: F07 | B26: Xác thực | C26: Đăng nhập bằng Wallet | D26: Đăng nhập/đăng ký bằng địa chỉ ví MetaMask; tạo user mới nếu chưa tồn tại; trả JWT. linked_wallet unique. | E26: Khách | F26: Rất cao
A27: F08 | B27: Người dùng | C27: Xem/cập nhật profile | D27: Xem thông tin cá nhân (GET /users/me) và cập nhật name (PUT /users/me). | E27: User | F27: Cao
A28: F09 | B28: Người dùng | C28: Xác thực OTP tài khoản | D28: Gửi OTP qua email để xác thực tài khoản; cập nhật is_verified = 1. | E28: User | F28: Cao
A29: F10 | B29: Người dùng | C29: Xem profile công khai | D29: Xem thông tin công khai của user khác: name, role, dự án, lịch sử donate. Không lộ email/google_sub. | E29: Khách/User | F29: Trung bình
A30: F11 | B30: Dự án | C30: Xem lịch sử donate của project | D30: Hiển thị danh sách tất cả lượt quyên góp cho một dự án: donor, số tiền, thời gian, trạng thái. | E30: Khách/User | F30: Cao
A31: F12 | B31: Quyên góp | C31: Donate crypto cho dự án | D31: Tạo donation (PENDING) qua API, gọi smart contract donate(), sau đó confirm crypto với tx hash → CONFIRMED. | E31: User | F31: Rất cao
... A38: F19 | B38: Quản trị | C38: Tạo Vault on-chain cho project | D38: Admin upload metadata lên IPFS, gọi Factory.createVault() on-chain, lưu vault_address vào DB. | E38: Admin | F38: Rất cao
A40: Đạt
A41: F01 | B41: User | C41: Đăng nhập Google | D41: Đăng nhập nhanh thông qua Google OAuth2, tự động tạo tài khoản nếu lần đầu truy cập. | E41: Khách | F41: Rất cao
A42: F02 | B42: User | C42: Xem danh sách dự án | D42: Hiển thị các dự án thiện nguyện với thông tin tiêu đề, mô tả ngắn, số tiền mục tiêu và tiến độ. | E42: Khách | F42: Rất cao
A43: F03 | B43: User | C43: Xem chi tiết dự án | D43: Xem thông tin chi tiết, lịch sử quyên góp của dự án, các cập nhật từ chủ dự án. | E43: Khách | F43: Rất cao
A44: F04 | B44: User | C44: Quyên góp qua VNPay | D44: Tạo URL thanh toán, thực hiện giao dịch qua cổng VNPay và xác nhận kết quả. | E44: Người dùng | F44: Rất cao
A45: F05 | B45: System | C45: Hệ thống điểm & Rank | D45: Tính tổng điểm (dựa trên số tiền quyên góp) và tự động cấp Badge tương ứng. | E45: Hệ thống | F45: Cao
A46: F06 | B46: User | C46: Quản lý Badge | D46: Người dùng có thể xem các Badge đã đạt được và chọn Badge hiển thị trên Profile. | E46: Người dùng | F46: Trung bình
A47: F07 | B47: System | C47: Xác thực JWT | D47: Cấp và kiểm tra Access Token/Refresh Token để bảo mật các API yêu cầu quyền đăng nhập. | E47: Hệ thống | F47: Rất cao
A48: 2. Quy tắc nghiệp vụ
A49: Mã | B49: Quy tắc | C49: Áp dụng cho | D49: Kỳ vọng kiểm thử
A50: BR01 | B50: Email đăng ký phải là duy nhất trong hệ thống. | C50: Đăng ký tài khoản | D50: Chặn đăng ký trùng email, trả về thông báo rõ ràng.
...

Sheet 2_Ke_hoach_kiem_thu
A1: KẾ HOẠCH KIỂM THỬ (KHÔNG BAO GỒM UNIT TEST)
A3: A. Kế hoạch tổng thể
A4: Hạng mục | B4: Nội dung
A5: Mục tiêu | B5: Xác minh luồng nghiệp vụ chính của web quyên góp từ thiện hoạt động đúng từ frontend -> API -> DB; phát hiện lỗi tích hợp, lỗi chức năng và rủi ro hệ thống trước khi demo/nghiệm thu.
A6: Phạm vi kiểm thử | B6: Bao gồm: kiểm thử tích hợp, kiểm thử chức năng, kiểm thử hệ thống (UI, hiệu năng cơ bản, bảo mật cơ bản, tương thích trình duyệt, khả năng sử dụng).
A7: Ngoài phạm vi | B7: Không lập kế hoạch unit test theo yêu cầu; không kiểm thử chuyên sâu cho hạ tầng production, backup/restore, thanh toán thật ngoài sandbox.
A8: Đối tượng kiểm thử | B8: Frontend React.js, Backend Node.js/Express.js, MySQL, cơ chế JWT/bcrypt, module chiến dịch, quyên góp, quản trị, thống kê.
A9: Chiến lược | B9: 1) Kiểm thử tích hợp API-DB và frontend-API cho các luồng chính. 2) Kiểm thử chức năng theo use case người dùng/admin. 3) Kiểm thử hệ thống end-to-end + UI + phi chức năng trọng yếu.
A10: Môi trường | B10: Test/Staging dùng dữ liệu mẫu; trình duyệt Chrome/Edge; thiết bị desktop và mobile viewport; CSDL MySQL test; thanh toán ở chế độ mô phỏng hoặc sandbox.
A11: Công cụ | B11: Postman/Newman (API), Playwright (UI regression/cross-browser cơ bản), Lighthouse (hiệu năng + accessibility + best practices), JMeter (tải), OWASP ZAP (quét bảo mật), Excel để quản lý test case.
A12: Tiêu chí bắt đầu | B12: Tài liệu yêu cầu/use case ổn định; build deploy được lên môi trường test; DB test sẵn dữ liệu; API chính sẵn sàng; quyền truy cập test đầy đủ.
A13: Tiêu chí kết thúc | B13: 100% test case ưu tiên cao được chạy; không còn lỗi nghiêm trọng (Blocker/Critical) ở luồng đăng nhập, xem chiến dịch, quyên góp, quản trị chiến dịch; tỷ lệ pass mục tiêu >= 85%.
A14: Đầu ra | B14: Bộ test design, test case, log lỗi, test report, danh sách rủi ro còn tồn tại, đề xuất cải tiến trước demo.
A15: Rủi ro | B15: Yêu cầu thanh toán/sandbox thay đổi; dữ liệu test không đủ; lỗi phân quyền/đồng bộ current_amount; môi trường test không ổn định; thời gian kiểm thử ngắn.
A17: B. Lịch thực hiện kiểm thử
A18: Giai đoạn | B18: Nội dung | C18: Loại kiểm thử | D18: Đầu vào | E18: Đầu ra | F18: Người phụ trách | G18: Thời lượng dự kiến
A19: 1. Chuẩn bị | B19: Rà soát yêu cầu, tạo dữ liệu test, cấu hình môi trường, xác định tool | C19: Chuẩn bị | D19: Tài liệu yêu cầu, source code, DB test | E19: Checklist sẵn sàng | F19: QA/nhóm dự án | G19: 0.5 ngày
A20: 2. Kiểm thử tích hợp | B20: Kiểm tra luồng frontend-API-DB: auth, chiến dịch, donation, transaction, thống kê | C20: Tích hợp | D20: API + DB sẵn sàng | E20: Kết quả tích hợp, defect log | F20: QA + Dev backend/frontend | G20: 1 ngày
A21: 3. Kiểm thử chức năng | B21: Chạy test theo use case người dùng và admin | C21: Chức năng | D21: Build ổn định sau fix tích hợp | E21: Biên bản pass/fail chức năng | F21: QA | G21: 1 ngày
A22: 4. Kiểm thử hệ thống | B22: Kiểm thử end-to-end, giao diện, responsive, hiệu năng cơ bản, bảo mật cơ bản | C22: Hệ thống | D22: Bản build gần hoàn chỉnh | E22: Kết quả hệ thống + report tool | F22: QA | G22: 1 ngày
A23: 5. Re-test & Regression | B23: Xác nhận lỗi đã sửa, chạy lại ca quan trọng | C23: Tích hợp/Chức năng/Hệ thống | D23: Bản fix từ dev | E23: Tỷ lệ pass cuối | F23: QA | G23: 0.5 ngày
A24: 6. Tổng hợp báo cáo | B24: Tổng hợp số liệu, đánh giá chất lượng, đề xuất release/demo | C24: Báo cáo | D24: Kết quả test | E24: Test report | F24: QA/Leader | G24: 0.5 ngày
A26: C. Entry / Exit criteria
A27: Tiêu chí | B27: Nội dung
A28: Entry-01 | B28: Có tài khoản test cho user và admin.
A29: Entry-02 | B29: Có ít nhất 3 chiến dịch mẫu: đang hoạt động, đã kết thúc, đang ẩn.
A30: Entry-03 | B30: Có dữ liệu transaction với trạng thái success/failed để đối soát.
A31: Exit-01 | B31: Không còn lỗi Blocker/Critical ở các luồng chính.
A32: Exit-02 | B32: Các lỗi Major còn lại có workaround chấp nhận được hoặc đã thống nhất xử lý sau demo.
A33: Exit-03 | B33: Test report được cập nhật đầy đủ số liệu thực thi và đánh giá rủi ro còn lại.

Sheet 3_Thiet_ke_kiem_thu
A1: THIẾT KẾ KIỂM THỬ
A2: Ghi chú | B2: Bao gồm kiểm thử chức năng, tích hợp, giao diện và phi chức năng trọng yếu.
A4: Ma trận thiết kế kiểm thử
A5: Mã TK | B5: Mức kiểm thử | C5: Chức năng/Đối tượng | D5: Test cái gì? | E5: Dữ liệu/Điều kiện chính | F5: Kỹ thuật thiết kế | G5: Ưu tiên
A6: TD01 | B6: Tích hợp | C6: Đăng ký tài khoản | D6: Kiểm tra frontend gửi đúng payload; API tạo user; DB lưu user mới với role=user và password đã băm. | E6: Email hợp lệ, email trùng, mật khẩu trống/không hợp lệ | F6: Phân lớp tương đương, dữ liệu âm | G6: Rất cao
A7: TD02 | B7: Tích hợp | C7: Đăng nhập | D7: Kiểm tra xác thực, cấp JWT, lưu session/token ở frontend, chặn sai mật khẩu. | E7: Tài khoản hợp lệ/không hợp lệ | F7: Phân lớp tương đương | G7: Rất cao
A8: TD03 | B8: Chức năng | C8: Danh sách chiến dịch | D8: Kiểm tra hiển thị đúng title, target_amount, current_amount, status, ngày bắt đầu/kết thúc; phân trang/tìm kiếm nếu có. | E8: Có chiến dịch active/hidden/ended | F8: Kiểm tra hiển thị dữ liệu | G8: Cao
A9: TD04 | B9: Chức năng | C9: Chi tiết chiến dịch | D9: Kiểm tra nội dung chi tiết, ảnh, tiến độ, trạng thái chiến dịch, nút Quyên góp. | E9: Campaign id hợp lệ/không hợp lệ | F9: Phân lớp tương đương | G9: Cao
A10: TD05 | B10: Tích hợp | C10: Quyên góp thành công | D10: Kiểm tra tạo donation, transaction success, current_amount tăng đúng, lịch sử hiển thị đúng. | E10: User đăng nhập, campaign active, amount hợp lệ | F10: Luồng end-to-end | G10: Rất cao
A11: TD06 | B11: Tích hợp | C11: Quyên góp thất bại | D11: Kiểm tra transaction failed thì không cộng current_amount và hiển thị thông báo phù hợp. | E11: Mô phỏng lỗi thanh toán | F11: Luồng thay đổi trạng thái | G11: Rất cao
A12: TD07 | B12: Chức năng | C12: Lịch sử quyên góp | D12: Kiểm tra chỉ hiển thị dữ liệu của người dùng hiện tại; đúng số tiền, thời gian, trạng thái. | E12: Nhiều donation của nhiều user | F12: Phân quyền dữ liệu | G12: Trung bình
A13: TD08 | B13: Chức năng | C13: Quản lý chiến dịch (Admin) | D13: Kiểm tra tạo/sửa/ẩn-hiện chiến dịch; validate trường bắt buộc; dữ liệu hiển thị đồng nhất user/admin. | E13: Admin login | F13: CRUD + kiểm tra validate | G13: Rất cao
A14: TD09 | B14: Chức năng | C14: Quản lý người dùng (Admin) | D14: Kiểm tra xem danh sách user, role, trạng thái; chặn user thường truy cập trang admin. | E14: Admin và user thường | F14: Role-based access | G14: Cao
A15: TD10 | B15: Tích hợp | C15: Dashboard thống kê | D15: Kiểm tra số liệu tổng tiền, số lượt donate, số chiến dịch khớp DB. | E15: Có dữ liệu mẫu trong DB | F15: Đối soát dữ liệu | G15: Cao
A16: TD11 | B16: Hệ thống/UI | C16: Form đăng ký/đăng nhập | D16: Kiểm tra label, placeholder, thông báo lỗi, focus, tab order, căn lề, nút bấm, responsive. | E16: Desktop + mobile viewport | F16: Checklist UI | G16: Cao
... A23: TD18 | B23: Hệ thống/Phi chức năng | C23: Tương thích | D23: Chạy smoke test trên Chrome/Edge và viewport mobile; kiểm tra sai khác hiển thị nghiêm trọng. | E23: Playwright hoặc test trình duyệt | F23: Cross-browser | G23: Trung bình
A26: Hải
A27: TD01 | B27: Unit | C27: HopeFundFactory — createVault | D27: Kiểm tra operator tạo vault đúng; vault address khác 0; event VaultCreated phát ra; vaults[projectId] lưu đúng; totalVaults tăng. | E27: projectId hợp lệ, founder hợp lệ, adminSigner hợp lệ, metaHash hợp lệ | F27: Phân lớp tương đương, dữ liệu âm | G27: Rất cao
A28: TD02 | B28: Unit | C28: HopeFundFactory — validate | D28: Kiểm tra revert khi: projectId đã tồn tại vault; founder = address(0); adminSigner = address(0); người gọi không phải operator. | E28: projectId trùng, address(0), account khác operator | F28: Dữ liệu âm, boundary | G28: Rất cao
A29: TD03 | B29: Unit | C29: HopeFundFactory — setOperator | D29: Kiểm tra chuyển quyền operator; event OperatorChanged; chặn chuyển cho address(0). | E29: newOperator hợp lệ, address(0) | F29: Phân lớp tương đương | G29: Cao
A30: TD04 | B30: Unit | C30: HopeFundVault — donate | D30: Kiểm tra donate >= MIN_DONATION thành công; totalDonated tăng; event Donated; chặn donate < MIN_DONATION; chặn khi paused. | E30: amount = 1e18 (pass), 1e16 (fail), 1e17 (boundary), paused state | F30: Giá trị biên, Pausable | G30: Rất cao
A31: TD05 | B31: Unit | C31: HopeFundVault — claim (EIP-712) | D31: Kiểm tra founder claim với signature hợp lệ; totalClaimed tăng; usedNonce = true; chặn: sai signer, nonce đã dùng, deadline hết hạn, amount > balance, người gọi không phải founder. | E31: signature hợp lệ/giả, nonce mới/đã dùng, deadline future/past, balance đủ/không đủ | F31: Bảng quyết định, replay attack | G31: Rất cao
A32: TD06 | B32: Unit | C32: HopeFundVault — pause/unpause | D32: Kiểm tra adminSigner pause chặn donate/claim; unpause khôi phục hoạt động; chặn người khác gọi pause. | E32: adminSigner vs non-adminSigner | F32: Phân quyền, trạng thái | G32: Cao
A33: TD07 | B33: Unit | C33: HopeFundVault — setAdminSigner | D33: Kiểm tra thay đổi adminSigner; event AdminSignerChanged; chặn address(0); chặn người không phải adminSigner. | E33: newSigner hợp lệ/address(0) | F33: Phân lớp tương đương | G33: Trung bình
A34: TD08 | B34: Tích hợp | C34: Wallet login | D34: Kiểm tra API tạo user mới khi wallet chưa tồn tại; trả JWT; tìm user cũ khi wallet đã tồn tại; chặn wallet rỗng. | E34: wallet mới, wallet đã tồn tại, wallet rỗng/null | F34: Phân lớp tương đương | G34: Rất cao
A35: TD09 | B35: Chức năng | C35: Quản lý profile user | D35: Kiểm tra GET /users/me trả đúng info; PUT /users/me cập nhật name; profile công khai không lộ email. | E35: JWT hợp lệ, name mới, userId tồn tại | F35: Phân quyền dữ liệu | G35: Cao
A36: TD10 | B36: Tích hợp | C36: OTP xác thực tài khoản | D36: Kiểm tra gửi OTP → verify OTP đúng → is_verified = 1; OTP sai → is_verified = 0. | E36: OTP đúng/sai | F36: Phân lớp tương đương | G36: Cao
A37: TD11 | B37: Tích hợp | C37: Xem donations của project | D37: Kiểm tra API trả đúng danh sách donations; project không tồn tại trả 404/rỗng. | E37: projectId có donations, projectId = 999999 | F37: Phân lớp tương đương | G37: Cao
A38: TD12 | B38: Tích hợp | C38: Donate crypto end-to-end | D38: Kiểm tra luồng: API tạo donation PENDING → contract donate() → confirm crypto → CONFIRMED; chặn donate cho project không có vault; chặn khi chưa login. | E38: project có vault/không có vault, tx hash hợp lệ/không hợp lệ | F38: Luồng end-to-end | G38: Rất cao
... A45: TD19 | B45: Hệ thống/Phi chức năng | C45: Hiệu năng + Tương thích | D45: Đo response time API withdraw/donations < 2s; responsive trang donate/withdraw trên mobile. | E45: JMeter 50 VU, viewport 375px/768px/1440px | F45: Load test, responsive | G45: Cao
A47: Đạt
A48: TD01 | B48: Unit/Integration | C48: Google Login | D48: Khả năng xác thực token Google và tạo/lấy user từ DB. | E48: ID Token hợp lệ từ Google, User mới/cũ. | F48: Phân vùng tương đương, Bảng quyết định. | G48: Rất cao
A49: TD02 | B49: System | C49: VNPay Payment | D49: Quy trình tạo URL và xử lý callback từ VNPay (Checksum/Return). | E49: vnp_Amount, vnp_TxnRef, mã phản hồi (00/01/24). | F49: Phân tích giá trị biên, Bảng quyết định. | G49: Rất cao
A50: TD03 | B50: Integration | C50: Point System | D50: Logic cộng điểm tích lũy và gán Badge sau khi thanh toán. | E50: Tổng số tiền quyên góp, mốc min_points của Badge. | F50: Kịch bản nghiệp vụ (Scenario). | G50: Cao
A51: TD04 | B51: UI/UX | C51: Project Listing | D51: Hiển thị danh sách dự án, phân trang và lọc theo Category. | E51: API /projects, Category slug. | F51: Kiểm thử giao diện, Responsive. | G51: Cao
A52: TD05 | B52: Security | C52: JWT Auth | D52: Quyền truy cập các API bảo mật (Private routes). | E52: Access token hết hạn, token bị sửa đổi, không có token. | F52: Kiểm thử tiêu cực (Negative). | G52: Rất cao
A53: TD06 | B53: Integration | C53: Auth Session | D53: Luồng làm mới Token (Refresh Token) khi Access Token hết hạn. | E53: Refresh Token hợp lệ/hết hạn. | F53: Luồng điều khiển (Control Flow). | G53: Trung bình
A54: TD07 | B54: Functional | C54: User Profile | D54: Thay đổi thông tin cá nhân (Tên, Email, Liên kết ví). | E54: Input hợp lệ, Email đã tồn tại, Wallet sai định dạng. | F54: Phân vùng tương đương. | G54: Trung bình
A55: TD08 | B55: Integration | C55: Project Stats | D55: Hiển thị tiến độ và số tiền đạt được dựa trên Donations thực tế. | E55: Tổng amount thuộc project so với goal_amount. | F55: Đối chiếu dữ liệu (Data comparison). | G55: Cao
A56: TD09 | B56: Security | C56: SQLi/XSS | D56: Khả năng chống các cuộc tấn công injection qua Form nhập liệu. | E56: Payload script, SQL command trong Search/Form. | F56: Penetration Test (Cơ bản). | G56: Rất cao
...

Sheet 4_Test_Case
A1: BỘ TEST CASE
A2: Lưu ý | B2: Các test phi chức năng ưu tiên dùng công cụ tự động: Lighthouse, JMeter, OWASP ZAP, Playwright, Postman/Newman.
A4: TC ID | B4: Mức KT | C4: Nhóm | D4: Tên test | E4: Mục tiêu | F4: Tiền điều kiện | G4: Bước thực hiện | H4: Dữ liệu test | I4: Kết quả mong đợi | J4: Hình thức | K4: Công cụ | L4: Ưu tiên | M4: Kết quả
A5: TC01 | B5: Chức năng | C5: Xác thực | D5: Đăng ký tài khoản hợp lệ | E5: Tạo được user mới với dữ liệu hợp lệ | F5: Chưa tồn tại email trong hệ thống | G5: 1. Mở form đăng ký 2. Nhập họ tên, email, mật khẩu hợp lệ 3. Nhấn Đăng ký | H5: name=Nguyen A; email=nguyena@test.com; password=Abc@1234 | I5: Thông báo đăng ký thành công; bản ghi user được tạo; role=user | J5: Manual | K5: UI + DB check | L5: Cao | M5: Pass
A6: TC02 | B6: Chức năng | C6: Xác thực | D6: Đăng ký với email trùng | E6: Chặn tạo tài khoản trùng email | F6: Email đã tồn tại | G6: 1. Mở form đăng ký 2. Nhập email đã tồn tại 3. Nhấn Đăng ký | H6: email=existing@test.com | I6: Hệ thống báo email đã tồn tại; không tạo thêm user | J6: Manual | K6: UI + DB check | L6: Cao | M6: Pass
A7: TC03 | B7: Tích hợp | C7: Xác thực | D7: Đăng nhập hợp lệ | E7: API xác thực đúng và frontend lưu JWT | F7: Tài khoản hợp lệ đã được tạo | G7: 1. Mở form đăng nhập 2. Nhập email/mật khẩu đúng 3. Nhấn Đăng nhập | H7: existing@test.com / Abc@1234 | I7: Đăng nhập thành công; nhận JWT; chuyển tới trang phù hợp | J7: Semi-auto | K7: Postman + UI | L7: Rất cao | M7: Pass
A8: TC04 | B8: Chức năng | C8: Xác thực | D8: Đăng nhập sai mật khẩu | E8: Từ chối đăng nhập khi sai thông tin | F8: Tài khoản tồn tại | G8: 1. Nhập email đúng 2. Nhập mật khẩu sai 3. Nhấn Đăng nhập | H8: existing@test.com / Sai123! | I8: Thông báo sai thông tin đăng nhập; không tạo phiên | J8: Manual | K8: UI | L8: Cao | M8: Pass
A9: TC05 | B9: Chức năng | C9: Phân quyền | D9: User chưa đăng nhập truy cập lịch sử quyên góp | E9: Chặn truy cập trái phép trang yêu cầu đăng nhập | F9: Đã logout | G9: 1. Truy cập URL /donation-history | H9: - | I9: Chuyển hướng đến đăng nhập hoặc báo chưa xác thực | J9: Manual | K9: Browser | L9: Cao | M9: Pass
A10: TC06 | B10: Chức năng | C10: Chiến dịch | D10: Hiển thị danh sách chiến dịch | E10: Hiển thị đúng danh sách chiến dịch công khai | F10: Có dữ liệu campaign mẫu | G10: 1. Mở trang chiến dịch | H10: - | I10: Danh sách hiển thị đúng title, tiến độ, trạng thái hiển thị cho user | J10: Manual | K10: Browser | L10: Cao | M10: Pass
A11: TC07 | B11: Chức năng | C11: Chiến dịch | D11: Xem chi tiết chiến dịch hợp lệ | E11: Hiển thị đủ thông tin của 1 campaign | F11: Campaign đang hoạt động tồn tại | G11: 1. Nhấn vào 1 campaign từ danh sách | H11: campaign_id hợp lệ | I11: Hiển thị mô tả, ảnh, mục tiêu, đã quyên góp, thời gian | J11: Manual | K11: Browser | L11: Cao | M11: Pass
A12: TC08 | B12: Chức năng | C12: Chiến dịch | D12: Mở chi tiết với campaign_id không tồn tại | E12: Xử lý lỗi tài nguyên không tồn tại | F12: Không có campaign_id đó | G12: 1. Truy cập URL chi tiết với id sai | H12: campaign_id=999999 | I12: Hiển thị 404/thông báo phù hợp; không vỡ giao diện | J12: Manual | K12: Browser | L12: Trung bình | M12: Pass
A13: TC09 | B13: Tích hợp | C13: Quản trị chiến dịch | D13: Admin tạo chiến dịch mới | E13: Tạo mới thành công qua UI -> API -> DB | F13: Admin đã đăng nhập | G13: 1. Vào trang admin campaign 2. Nhấn Tạo mới 3. Nhập dữ liệu hợp lệ 4. Lưu | H13: title, target_amount, dates hợp lệ | I13: Campaign được tạo và xuất hiện ở danh sách admin | J13: Semi-auto | K13: Postman + UI | L13: Rất cao | M13: Pass
A14: TC10 | B14: Tích hợp | C14: Quản trị chiến dịch | D14: Admin sửa chiến dịch | E14: Cập nhật campaign đúng và đồng bộ giao diện người dùng | F14: Admin đã đăng nhập; campaign tồn tại | G14: 1. Chọn campaign 2. Cập nhật mô tả/target 3. Lưu | H14: target_amount mới | I14: Dữ liệu cập nhật thành công, hiển thị đúng ở detail | J14: Semi-auto | K14: Postman + UI | L14: Cao | M14: Pass
A15: TC11 | B15: Chức năng | C15: Quản trị chiến dịch | D15: Ẩn chiến dịch khỏi danh sách user | E15: Campaign hidden không hiển thị cho user công khai | F15: Admin đã đăng nhập; campaign tồn tại | G15: 1. Admin ẩn campaign 2. Mở trang user | H15: - | I15: Campaign không còn trong danh sách user | J15: Manual | K15: Browser | L15: Cao | M15: Fail
... A39: TC35 | B39: Chức năng | C39: Quản trị chiến dịch | D39: Validate trường bắt buộc khi tạo campaign | E39: Không cho lưu campaign thiếu title/target/date | F39: Admin đã đăng nhập | G39: 1. Mở form tạo campaign 2. Bỏ trống trường bắt buộc 3. Lưu | H39: title trống; target_amount trống | I39: Thông báo lỗi rõ ràng; không tạo dữ liệu | J39: Manual | K39: Browser | L39: Cao | M39: Pass
A42: Hải
A43: TC01 | B43: Unit | C43: Smart Contract | D43: Tạo vault cho project hợp lệ | E43: Verify Factory.createVault deploy đúng vault | F43: Contract deployed; operator account sẵn sàng | G43: 1. Operator gọi createVault(projectId=1, founder, adminSigner, metaHash) | H43: projectId=1; founder=0xFounder; adminSigner=0xAdmin; metaHash=0xabc | I43: Vault deployed thành công; event VaultCreated phát ra; vaults[1] trả địa chỉ vault; totalVaults() = 1 | J43: Auto | K43: Hardhat | L43: Rất cao | M43: Pass
A44: TC02 | B44: Unit | C44: Smart Contract | D44: Tạo vault cho projectId đã tồn tại | E44: Chặn tạo vault trùng | F44: Vault cho projectId=1 đã tồn tại | G44: 1. Gọi createVault(projectId=1, ...) lần 2 | H44: projectId=1 (đã có vault) | I44: Revert "Vault already exists for this project" | J44: Auto | K44: Hardhat | L44: Cao | M44: Pass
A45: TC03 | B45: Unit | C45: Smart Contract | D45: Người không phải operator tạo vault | E45: Chỉ operator được tạo vault | F45: Dùng account không phải operator | G45: 1. Từ account khác, gọi createVault(...) | H45: account = user thường | I45: Revert "Caller is not the operator" | J45: Auto | K45: Hardhat | L45: Rất cao | M45: Pass
A46: TC04 | B46: Unit | C46: Smart Contract | D46: Tạo vault với founder = address(0) | E46: Validate địa chỉ đầu vào | F46: Contract đã deploy | G46: 1. Gọi createVault(..., founder=address(0), ...) | H46: founder = 0x0000...0000 | I46: Revert "Invalid founder address" | J46: Auto | K46: Hardhat | L46: Cao | M46: Pass
A47: TC05 | B47: Unit | C47: Smart Contract | D47: Chuyển quyền operator | E47: Verify setOperator hoạt động | F47: Operator hiện tại gọi | G47: 1. Gọi setOperator(newOperator) 2. Kiểm tra biến operator | H47: newOperator = 0xNewOp | I47: operator == newOperator; event OperatorChanged phát ra | J47: Auto | K47: Hardhat | L47: Cao | M47: Pass
A48: TC06 | B48: Unit | C48: Smart Contract | D48: Donate token hợp lệ vào vault | E48: Verify donate thành công | F48: Vault deployed; user có USDT; đã approve token cho vault | G48: 1. User approve vault spend USDT 2. Gọi vault.donate(1e18) | H48: amount = 1 USDT (1e18 wei) | I48: Token chuyển vào vault; totalDonated += 1e18; event Donated phát ra | J48: Auto | K48: Hardhat | L48: Rất cao | M48: Pass
A49: TC07 | B49: Unit | C49: Smart Contract | D49: Donate dưới mức tối thiểu | E49: Chặn donate < MIN_DONATION | F49: Vault deployed | G49: 1. Gọi vault.donate(1e16) | H49: amount = 0.01 USDT (1e16 wei) | I49: Revert "Amount below minimum donation" | J49: Auto | K49: Hardhat | L49: Cao | M49: Pass
A50: TC08 | B50: Unit | C50: Smart Contract | D50: Donate đúng mức tối thiểu (boundary) | E50: Verify giá trị biên MIN_DONATION | F50: Vault deployed; user có USDT | G50: 1. Gọi vault.donate(1e17) | H50: amount = 0.1 USDT (1e17 wei) = MIN_DONATION | I50: Donate thành công; totalDonated += 1e17 | J50: Auto | K50: Hardhat | L50: Cao | M50: Pass
A51: TC09 | B51: Unit | C51: Smart Contract | D51: Founder claim với signature hợp lệ | E51: Verify claim EIP-712 end-to-end | F51: Vault có balance >= amount; admin đã ký | G51: 1. Admin ký EIP-712 (projectId, founder, amount, nonce, deadline) 2. Founder gọi claim(amount, nonce, deadline, signature) | H51: amount=5e18; nonce=1; deadline=future | I51: Token chuyển cho founder; totalClaimed += 5e18; usedNonce[1]=true; event Claimed | J51: Auto | K51: Hardhat | L51: Rất cao | M51: Pass
A52: TC10 | B52: Unit | C52: Smart Contract | D52: Claim với nonce đã sử dụng (replay attack) | E52: Chống replay attack | F52: Nonce=1 đã dùng ở TC09 | G52: 1. Gọi claim(..., nonce=1, ...) lần 2 với cùng tham số | H52: nonce=1 (đã dùng) | I52: Revert "Nonce already used" | J52: Auto | K52: Hardhat | L52: Rất cao | M52: Pass
A53: TC11 | B53: Unit | C53: Smart Contract | D53: Claim khi signature hết hạn | E53: Verify deadline check | F53: Vault có balance | G53: 1. Tạo signature với deadline = block.timestamp - 1 2. Gọi claim | H53: deadline đã quá hạn | I53: Revert "Signature expired" | J53: Auto | K53: Hardhat | L53: Cao | M53: Pass
A54: TC12 | B54: Unit | C54: Smart Contract | D54: Claim với signature sai admin | E54: Verify EIP-712 signer check | F54: Vault có balance | G54: 1. Ký bằng account không phải adminSigner 2. Gọi claim | H54: signature từ random account | I54: Revert "Invalid signature" | J54: Auto | K54: Hardhat | L54: Rất cao | M54: Pass
... A92: TC50 | B92: Hệ thống | C92: An toàn đầu vào | D92: SQL Injection tại wallet login | E92: Chống SQL injection | F92: Endpoint login hoạt động | G92: 1. POST /auth/wallet/login {walletAddress: "' OR '1'='1"} | H92: walletAddress = "' OR '1'='1" | I92: Đăng nhập thất bại; response an toàn; không lỗi SQL lộ ra | J92: Auto | K92: Postman/Newman | L92: Rất cao | M92: Pass
A94: Đạt
A95: TC01 | B95: System | C95: Auth | D95: Login thành công | E95: Kiểm tra Google Login | F95: Có tài khoản Google | G95: Đăng nhập -> Chọn tài khoản | H95: Google ID Token | I95: Trả về AccessToken, Lưu session | J95: Browser | K95: Browser | L95: Rất cao | M95: Pass
A96: TC02 | B96: System | C96: Auth | D96: Login sai Token | E96: Kiểm tra login Token lỗi | F96: Token không hợp lệ | G96: Gửi ID Token sai đến API | H96: Invalid Token | I96: Trả về lỗi 401 Unauthorized | J96: Auto | K96: Postman | L96: Cao | M96: Pass
A97: TC03 | B97: System | C97: Auth | D97: Token hết hạn | E97: Kiểm tra JWT expire | F97: Token hết 15 phút | G97: Truy cập API sau 15 phút | H97: AccessToken cũ | I97: Yêu cầu Login lại/Refresh token | J97: Auto | K97: Postman | L97: Cao | M97: Pass
A98: TC04 | B98: System | C98: Auth | D98: Refresh Token | E98: Lấy token mới | F98: Có RefreshToken hợp lệ | G98: Gọi API /refresh | H98: RefreshToken | I98: API cấp AccessToken mới | J98: Auto | K98: Postman | L98: Trung bình | M98: Pass
A99: TC05 | B99: System | C99: Auth | D99: Logout | E99: Đăng xuất người dùng | F99: Đang đăng nhập | G99: Click Đăng xuất | H99: None | I99: Xóa token Browser, Về trang chủ | J99: Browser | K99: Browser | L99: Thấp | M99: Pass
A100: TC06 | B100: Security | C100: Auth | D100: Truy cập trái phép | E100: Quyền vào Profile | F100: Chưa đăng nhập | G100: Vào link /profile trực tiếp | H100: None | I100: Bị chặn, redirect về Signin | J100: Browser | K100: Browser | L100: Rất cao | M100: Pass
A101: TC07 | B101: System | C101: Auth | D101: Đăng ký mới (First) | E101: User mới qua Google | F101: Email chưa có trong DB | G101: Login lần đầu qua Google | H101: Email mới | I101: Tạo bản ghi User, gán Role 'USER' | J101: Manual | K101: DB Check | L101: Cao | M101: Pass
A102: TC08 | B102: Security | C102: Auth | D102: Sửa đổi Token | E102: Kiểm tra tính Integrity | F102: Token bị sửa Signature | G102: Gửi token đã sửa lên API | H102: Tampered JWT | I102: Hệ thống báo token không hợp lệ | J102: Auto | K102: Postman | L102: Rất cao | M102: Pass
A103: TC09 | B103: System | C103: VNPay | D103: Chuyển hướng VNPay | E103: Tạo URL thanh toán | F103: Project đang hoạt động | G103: Chọn Donation qua VNPay | H103: Amount: 100,000 | I103: Chuyển hướng sang sandbox VNPay | J103: Browser | K103: Browser | L103: Rất cao | M103: Pass
A104: TC10 | B104: System | C104: VNPay | D104: Thanh toán thành công | E104: Verify callback VNPay | F104: Giao dịch tại sandbox | G104: Hoàn tất trên VNPay -> Quay về | H104: ResponseCode: 00 | I104: Donation thành CONFIRMED | J104: Browser | K104: Postman | L104: Rất cao | M104: Pass
...

Sheet 5_Test_Report
A1: TEST REPORT
A2: Báo cáo tại ngày | B2: 46106 | D2: Nguồn dữ liệu | E2: Sheet 4_Test_Case
A4: A. Tổng quan thực thi
A5: Chỉ số | B5: Giá trị | C5: Công thức/ghi chú
A6: Tổng số test case | B6: =COUNTA('4_Test_Case'!A5:A1100) -> 119 | C6: Đếm số TC có mã
A7: Số test case đã thực hiện | B7: =COUNTIF('4_Test_Case'!M5:M1100,"Pass")+COUNTIF('4_Test_Case'!M5:M1100,"Fail") -> 110 | C7: Pass + Fail
A8: Số Pass | B8: =COUNTIF('4_Test_Case'!M5:M1100,"Pass") -> 103 | C8: Kết quả Pass
A9: Số Fail | B9: =COUNTIF('4_Test_Case'!M5:M1100,"Fail") -> 7 | C9: Kết quả Fail
A10: Số Not Run | B10: =COUNTIF('4_Test_Case'!M5:M1100,"Not Run") -> 6 | C10: Chưa chạy
A11: Tỷ lệ Pass / Tổng số | B11: =IF(B8=0,0,B8/B6) -> 0.86554622 | C11: Pass trên tổng số TC
A12: Tỷ lệ Pass / Đã thực hiện | B12: =IF(B7=0,0,B8/B7) -> 0.93636364 | C12: Pass trên TC đã chạy
A14: B. Thống kê theo mức kiểm thử
A15: Mức kiểm thử | B15: Tổng TC | C15: Pass | D15: Fail | E15: Not Run | F15: Tỷ lệ Pass
A16: Chức năng | B16: =COUNTIF('4_Test_Case'!B5:B1100,"Chức năng") -> 30 | C16: =COUNTIFS('4_Test_Case'!B5:B1100,"Chức năng",'4_Test_Case'!M5:M1100,"Pass") -> 29 | D16: =COUNTIFS('4_Test_Case'!B5:B1100,"Chức năng",'4_Test_Case'!M5:M1100,"Fail") -> 1 | E16: =COUNTIFS('4_Test_Case'!B5:B1100,"Chức năng",'4_Test_Case'!M5:M1100,"Not Run") -> 0 | F16: =IF(B16=0,0,C16/B16) -> 0.96666667
A17: Tích hợp | B17: =COUNTIF('4_Test_Case'!B5:B1100,"Tích hợp") -> 18 | C17: =COUNTIFS('4_Test_Case'!B5:B1100,"Tích hợp",'4_Test_Case'!M5:M1100,"Pass") -> 17 | D17: =COUNTIFS('4_Test_Case'!B5:B1100,"Tích hợp",'4_Test_Case'!M5:M1100,"Fail") -> 1 | E17: =COUNTIFS('4_Test_Case'!B5:B1100,"Tích hợp",'4_Test_Case'!M5:M1100,"Not Run") -> 0 | F17: =IF(B17=0,0,C17/B17) -> 0.94444444
A18: Hệ thống | B18: =COUNTIF('4_Test_Case'!B5:B1100,"Hệ thống") -> 20 | C18: =COUNTIFS('4_Test_Case'!B5:B1100,"Hệ thống",'4_Test_Case'!M5:M1100,"Pass") -> 14 | D18: =COUNTIFS('4_Test_Case'!B5:B1100,"Hệ thống",'4_Test_Case'!M5:M1100,"Fail") -> 3 | E18: =COUNTIFS('4_Test_Case'!B5:B1100,"Hệ thống",'4_Test_Case'!M5:M1100,"Not Run") -> 3 | F18: =IF(B18=0,0,C18/B18) -> 0.7
A20: C. Thống kê theo công cụ tự động cho test phi chức năng
A21: Công cụ | B21: Số TC liên quan | C21: Pass | D21: Fail | E21: Not Run | F21: Ghi chú
A22: Lighthouse | B22: =COUNTIF('4_Test_Case'!K5:K1100,"Lighthouse") -> 2 | C22: =COUNTIFS('4_Test_Case'!K5:K1100,"Lighthouse",'4_Test_Case'!M5:M1100,"Pass") -> 2 | D22: =COUNTIFS('4_Test_Case'!K5:K1100,"Lighthouse",'4_Test_Case'!M5:M1100,"Fail") -> 0 | E22: =COUNTIFS('4_Test_Case'!K5:K1100,"Lighthouse",'4_Test_Case'!M5:M1100,"Not Run") -> 0 | F22: Accessibility + Performance frontend
A23: JMeter | B23: =COUNTIF('4_Test_Case'!K5:K1100,"JMeter") -> 1 | C23: =COUNTIFS('4_Test_Case'!K5:K1100,"JMeter",'4_Test_Case'!M5:M1100,"Pass") -> 0 | D23: =COUNTIFS('4_Test_Case'!K5:K1100,"JMeter",'4_Test_Case'!M5:M1100,"Fail") -> 1 | E23: =COUNTIFS('4_Test_Case'!K5:K1100,"JMeter",'4_Test_Case'!M5:M1100,"Not Run") -> 0 | F23: Load test API
A24: OWASP ZAP | B24: =COUNTIF('4_Test_Case'!K5:K1100,"OWASP ZAP") -> 1 | C24: =COUNTIFS('4_Test_Case'!K5:K1100,"OWASP ZAP",'4_Test_Case'!M5:M1100,"Pass") -> 0 | D24: =COUNTIFS('4_Test_Case'!K5:K1100,"OWASP ZAP",'4_Test_Case'!M5:M1100,"Fail") -> 1 | E24: =COUNTIFS('4_Test_Case'!K5:K1100,"OWASP ZAP",'4_Test_Case'!M5:M1100,"Not Run") -> 0 | F24: Security scan cơ bản
A25: Playwright | B25: =COUNTIF('4_Test_Case'!K5:K1100,"Playwright") -> 3 | C25: =COUNTIFS('4_Test_Case'!K5:K1100,"Playwright",'4_Test_Case'!M5:M1100,"Pass") -> 2 | D25: =COUNTIFS('4_Test_Case'!K5:K1100,"Playwright",'4_Test_Case'!M5:M1100,"Fail") -> 0 | E25: =COUNTIFS('4_Test_Case'!K5:K1100,"Playwright",'4_Test_Case'!M5:M1100,"Not Run") -> 1 | F25: Responsive/Cross-browser/Smoke E2E
A26: Postman/Newman | B26: =COUNTIF('4_Test_Case'!K5:K1100,"Postman/Newman") -> 7 | C26: =COUNTIFS('4_Test_Case'!K5:K1100,"Postman/Newman",'4_Test_Case'!M5:M1100,"Pass") -> 7 | D26: =COUNTIFS('4_Test_Case'!K5:K1100,"Postman/Newman",'4_Test_Case'!M5:M1100,"Fail") -> 0 | E26: =COUNTIFS('4_Test_Case'!K5:K1100,"Postman/Newman",'4_Test_Case'!M5:M1100,"Not Run") -> 0 | F26: API auth, token, injection
A28: D. Nhận xét nhanh
A29: Kết quả hiện tại cho thấy các luồng lõi đa số đạt yêu cầu, tuy nhiên vẫn còn lỗi ở các điểm quan trọng như ẩn chiến dịch khỏi danh sách người dùng, đồng bộ current_amount khi giao dịch thất bại, loading/empty state, hiệu năng API tải đồng thời và cảnh báo bảo mật cơ bản. Cần ưu tiên sửa các lỗi Fail trước khi demo/nghiệm thu.
